Workbook
Name n_1: {"","одинz","дваz","триz","четыреz","пятьz","шестьz","семьz","восемьz","девятьz"}
Name n_2: {"десятьz","одиннадцатьz","двенадцатьz","тринадцатьz","четырнадцатьz","пятнадцатьz","шестнадцатьz","семнадцатьz","восемнадцатьz","девятнадцатьz"}
Name n_3: {"";1;"двадцатьz";"тридцатьz";"сорокz";"пятьдесятz";"шестьдесятz";"семьдесятz";"восемьдесятz";"девяностоz"}
Name n_4: {"","стоz","двестиz","тристаz","четырестаz","пятьсотz","шестьсотz","семьсотz","восемьсотz","девятьсотz"}
Name n_5: {"","однаz","двеz","триz","четыреz","пятьz","шестьz","семьz","восемьz","девятьz"}
Name n0: "000000000000"&MID(1/2,2,1)&"00"
Name n0x: IF(n_3=1,n_2,n_3&n_1)
Name n1x: IF(n_3=1,n_2,n_3&n_5)
Name договор: '[1]номера лотов'!$M$7:$M$10
Name мил: {0,"овz";1,"z";2,"аz";5,"овz"}
Name предмет: '[2]номера лотов'!$M$7:$M$9
Name СМР_ОКН: {"","одинz","дваz","триz","четыреz","пятьz","шестьz","семьz","восемьz","девятьz"}
Name тыс: {0,"тысячz";1,"тысячаz";2,"тысячиz";5,"тысячz"}

Sheet 380ккрдм-18_Шухова ул. 11I16
A1: Приложение № 1 | D1: 1 | BC1: =MID(CELL("filename",#REF!),SEARCH("]",CELL("filename"))+1,255) -> #REF! | BZ1: 1 | CA1: Лот (18)\Обоснование цены договора\
A2: к договору _____________ | D2: 1 | CA2: .xlsx
A3: от "____"________202__ | D3: 1 | BZ3: 1
D4: 1 | BZ4: 1
A5: График производства и стоимости работ | D5: 1 | BZ5: 1
AB6: =INDIRECT("'таблица стоимостей'!D"&#REF!&"") -> #REF! | BZ6: 1
A7: Наименование работ | C7: с НДС, с непредвиденными | D7: Стоимость | F7: 2025 г. | AJ7: 2026 г. | BT7: 2026г. | BZ7: 1
A8: 1 | B8: 1 | C8: 1 | D8: работ с ВЗиС, | F8: График работ (месяцы) | BZ8: 1
A9: 1 | B9: 1 | C9: 1 | D9: руб. | F9: март | I9: апрель | L9: май | O9: июнь | R9: июль | U9: август | X9: сентябрь | AA9: октябрь | AD9: ноябрь | AG9: декабрь | AJ9: январь | AM9: февраль | AP9: март | AS9: апрель | AV9: май | AY9: июнь | BB9: июль | BE9: август | BH9: сентябрь | BK9: октябрь | BN9: ноябрь | BQ9: декабрь | BT9: январь | BW9: февраль | BZ9: 1
A10: 1 | B10: 1 | C10: 1 | D10: 1 | F10: 1-10 | G10: 11-20 | H10: 21-31 | I10: 1-10 | J10: 11-20 | K10: 21-30 | L10: 1-10 | M10: 11-20 | N10: 21-31 | O10: 1-10 | P10: 11-20 | Q10: 21-30 | R10: 1-10 | S10: 11-20 | T10: * | U10: 1-10 | V10: 11-20 | W10: 21-31 | X10: 1-10 | Y10: 11-20 | Z10: 21-30 | AA10: 1-10 | AB10: * | AC10: 21-31 | AD10: 1-10 | AE10: 11-20 | AF10: 21-30 | AG10: 1-10 | AH10: 11-20 | AI10: 21-31 | AJ10: 1-10 | AK10: 11-20 | AL10: 21-31 | AM10: * | AO10: 21-28 | AQ10: 11-20 | AR10: * | AS10: 1-10 | AT10: 11-20 | AU10: 21-30 | AV10: 1-10 | AW10: 11-20 | AX10: 21-31 | AY10: 1-10 | AZ10: 11-20 | BA10: 21-30 | BB10: 1-10 | BC10: 11-20 | BD10: 21-31 | BE10: 1-10 | BF10: 11-20 | BG10: 21-31 | BH10: 1-10 | BI10: 11-20 | BJ10: 21-30 | BK10: 1-10 | BL10: 11-20 | BM10: 21-31 | BN10: 1-10 | BO10: 11-20 | BP10: 21-30 | BQ10: 1-10 | BR10: 11-20 | BS10: 21-31 | BT10: 1-10 | BU10: 11-20 | BV10: 21-31 | BW10: 1-10 | BX10: 11-20 | BY10: 21-28 | BZ10: 1
A11: Подготовительные работы | D11: 1 | AR11: р | AS11: р | AT11: р | AU11: р | AV11: р | BZ11: 1
A12: ремонт внутридомовых инженерных сетей электроснабжения | B12: 0 | C12: =INDEX([2]МГЭ!$A:$Q,MATCH($D$6,[2]МГЭ!$D:$D,0)+B12,17) -> #N/A | D12: 0 | AS12: 1 | AT12: 1 | AU12: 2 | AV12: 2 | AW12: 3 | AX12: 3 | AY12: 3 | AZ12: 4 | BA12: 4 | BB12: од | BC12: од | BZ12: 1
A13: ремонт внутридомовых инженерных систем газоснабжения | B13: 1 | C13: =INDEX([2]МГЭ!$A:$Q,MATCH($D$6,[2]МГЭ!$D:$D,0)+B13,17) -> #N/A | D13: 0 | AS13: 1 | AT13: 2 | AU13: 2 | AV13: 3 | AW13: 3 | AX13: 4 | AY13: 4 | AZ13: од | BA13: од | BZ13: 1
A14: ремонт инженерных систем холодного водоснабжения (стояки) | B14: 2 | C14: =INDEX([2]МГЭ!$A:$Q,MATCH($D$6,[2]МГЭ!$D:$D,0)+B14,17) -> #N/A | AW14: 1 | AX14: 1 | AY14: 1 | AZ14: 2 | BA14: 2 | BB14: 2 | BC14: 2 | BD14: 3 | BE14: 3 | BF14: 3 | BG14: 4 | BH14: 4 | BI14: р | BJ14: р | BZ14: 1
A15: ремонт внутридомовых инженерных систем холодного водоснабжения (разводящие магистрали) | B15: 3 | C15: =INDEX([2]МГЭ!$A:$Q,MATCH($D$6,[2]МГЭ!$D:$D,0)+B15,17) -> #N/A | D15: 0 | AW15: 1 | AX15: 1 | AY15: 2 | AZ15: 2 | BA15: 3 | BB15: 3 | BC15: 4 | BD15: 4 | BE15: 4 | BF15: 4 | BZ15: 1
A16: ремонт внутридомовых инженерных систем горячего водоснабжения (стояки) | B16: 4 | C16: =INDEX([2]МГЭ!$A:$Q,MATCH($D$6,[2]МГЭ!$D:$D,0)+B16,17) -> #N/A | D16: 0 | AW16: 1 | AX16: 1 | AY16: 1 | AZ16: 2 | BA16: 2 | BB16: 2 | BC16: 2 | BD16: 3 | BE16: 3 | BF16: 3 | BG16: 4 | BH16: 4 | BI16: р | BJ16: р | BZ16: 1
A17: ремонт внутридомовых инженерных систем горячего водоснабжения (разводящие магистрали) | B17: 5 | C17: =INDEX([2]МГЭ!$A:$Q,MATCH($D$6,[2]МГЭ!$D:$D,0)+B17,17) -> #N/A | D17: 0 | AW17: 1 | AX17: 1 | AY17: 2 | AZ17: 2 | BA17: 3 | BB17: 3 | BC17: 4 | BD17: 4 | BE17: 4 | BF17: 4 | BZ17: 1
A18: ремонт внутридомовых инженерных систем водоотведения (канализации) (стояки) | B18: 6 | C18: =INDEX([2]МГЭ!$A:$Q,MATCH($D$6,[2]МГЭ!$D:$D,0)+B18,17) -> #N/A | D18: 0 | AW18: 1 | AX18: 1 | AY18: 1 | AZ18: 2 | BA18: 2 | BB18: 2 | BC18: 2 | BD18: 3 | BE18: 3 | BF18: 3 | BG18: 4 | BH18: 4 | BI18: р | BJ18: р | BZ18: 1
A19: ремонт внутридомовых инженерных систем водоотведения (канализации) (выпуски и сборные трубопроводы) | B19: 7 | C19: =INDEX([2]МГЭ!$A:$Q,MATCH($D$6,[2]МГЭ!$D:$D,0)+B19,17) -> #N/A | D19: 0 | AW19: 1 | AX19: 1 | AY19: 2 | AZ19: 2 | BA19: 3 | BB19: 3 | BC19: 4 | BD19: 4 | BE19: 4 | BF19: 4 | BZ19: 1
A20: ремонт инженерных систем теплоснабжения (стояки) | B20: 8 | C20: =INDEX([2]МГЭ!$A:$Q,MATCH($D$6,[2]МГЭ!$D:$D,0)+B20,17) -> #N/A | AW20: 1 | AX20: 1 | AY20: 2 | AZ20: 2 | BA20: 3 | BB20: 3 | BC20: 3 | BD20: 4 | BE20: 4 | BF20: р | BG20: р | BZ20: 1
A21: ремонт внутридомовых инженерных систем теплоснабжения (разводящие магистрали) | B21: 9 | C21: =INDEX([2]МГЭ!$A:$Q,MATCH($D$6,[2]МГЭ!$D:$D,0)+B21,17) -> #N/A | D21: 0 | AW21: 1 | AX21: 1 | AY21: 2 | AZ21: 2 | BA21: 3 | BB21: 3 | BC21: 4 | BD21: 4 | BE21: 4 | BF21: 4 | BZ21: 1
A22: ремонт или замена мусоропровода | B22: 10 | C22: =INDEX([2]МГЭ!$A:$Q,MATCH($D$6,[2]МГЭ!$D:$D,0)+B22,17) -> #N/A | D22: 0 | AS22: 1 | AT22: 1 | AU22: 2 | AV22: 2 | AW22: 2 | AX22: 3 | AY22: 3 | AZ22: 4 | BA22: 4 | BB22: 4 | BC22: од | BD22: од | BZ22: 1
A23: ремонт внутридомовой системы дымоудаления и противопожарной автоматики | B23: 11 | C23: =INDEX([2]МГЭ!$A:$Q,MATCH($D$6,[2]МГЭ!$D:$D,0)+B23,17) -> #N/A | D23: 0 | AS23: 1 | AT23: 1 | AU23: 2 | AV23: 2 | AW23: 3 | AX23: 3 | AY23: 4 | AZ23: 4 | BA23: од | BB23: од | BZ23: 1
A24: ремонт пожарного водопровода | B24: 12 | C24: =INDEX([2]МГЭ!$A:$Q,MATCH($D$6,[2]МГЭ!$D:$D,0)+B24,17) -> #N/A | D24: 0 | AS24: 1 | AT24: 1 | AU24: 2 | AV24: 2 | AW24: 3 | AX24: 3 | AY24: 3 | AZ24: 4 | BA24: 4 | BB24: од | BC24: од | BZ24: 1
A25: ремонт фасада | B25: 13 | C25: =INDEX([2]МГЭ!$A:$Q,MATCH($D$6,[2]МГЭ!$D:$D,0)+B25,17) -> #N/A | D25: 0 | AT25: 1 | AU25: 2 | AV25: 2 | AW25: 2 | AX25: 2 | AY25: 3 | AZ25: 3 | BA25: 3 | BB25: 3 | BC25: 3 | BD25: 4 | BE25: 4 | BF25: од | BG25: од | BZ25: 1
A26: в т.ч. замена окон в местах общего пользования | B26: 14 | C26: =INDEX([2]МГЭ!$A:$Q,MATCH($D$6,[2]МГЭ!$D:$D,0)+B26,17) -> #N/A | D26: 0 | AT26: 1 | AU26: 2 | AV26: 2 | AW26: 2 | AX26: 2 | AY26: 3 | AZ26: 3 | BA26: 3 | BB26: 3 | BC26: 3 | BD26: 4 | BE26: 4 | BF26: од | BG26: од
A27: ремонт крыши | B27: 15 | C27: =INDEX([2]МГЭ!$A:$Q,MATCH($D$6,[2]МГЭ!$D:$D,0)+B27,17) -> #N/A | D27: 0 | AT27: 1 | AU27: 2 | AV27: 2 | AW27: 2 | AX27: 2 | AY27: 3 | AZ27: 3 | BA27: 3 | BB27: 3 | BC27: 3 | BD27: 4 | BE27: 4 | BF27: од | BG27: од | BZ27: 1
A28: ремонт фундамента | B28: 16 | C28: =INDEX([2]МГЭ!$A:$Q,MATCH($D$6,[2]МГЭ!$D:$D,0)+B28,17) -> #N/A | D28: 0 | AT28: 1 | AU28: 2 | AV28: 2 | AW28: 2 | AX28: 2 | AY28: 3 | AZ28: 3 | BA28: 3 | BB28: 3 | BC28: 3 | BD28: 4 | BE28: 4 | BF28: од | BG28: од | BZ28: 1
A29: ремонт или замена внутреннего водостока | B29: 17 | C29: =INDEX([2]МГЭ!$A:$Q,MATCH($D$6,[2]МГЭ!$D:$D,0)+B29,17) -> #N/A | D29: 0 | AS29: 1 | AT29: 1 | AU29: 1 | AV29: 2 | AW29: 2 | AX29: 2 | AY29: 3 | AZ29: 3 | BA29: 4 | BB29: 4 | BC29: од | BD29: од | BZ29: 1
A30: ремонт подвальных помещений, относящихся к общему имуществу собственников помещений | B30: 18 | C30: =INDEX([2]МГЭ!$A:$Q,MATCH($D$6,[2]МГЭ!$D:$D,0)+B30,17) -> #N/A | D30: 0 | AW30: 1 | AX30: 1 | AY30: 2 | AZ30: 2 | BA30: 3 | BB30: 3 | BC30: 3 | BD30: 4 | BE30: 4 | BF30: 4 | BG30: од | BH30: од | BZ30: 1
A31: ремонт подъездов, направленный на восстановление их надлежащего состояния и проводимый при выполнении иных работ по капитальному ремонту общего имущества в многоквартирном доме | B31: 19 | C31: =INDEX([2]МГЭ!$A:$Q,MATCH($D$6,[2]МГЭ!$D:$D,0)+B31,17) -> #N/A | D31: 0 | AT31: 1 | AU31: 1 | AV31: 1 | AW31: 2 | AX31: 2 | AY31: 2 | AZ31: 3 | BA31: 3 | BB31: 3 | BC31: 4 | BD31: 4 | BE31: 4 | BF31: 4 | BG31: од | BH31: од | BZ31: 1
A32: Подготовка и представление отчетной документации | D32: 1 | BG32: р | BH32: р | BI32: р | BJ32: р | BK32: р | BL32: р | BM32: р | BN32: р | BO32: р | BP32: од
A33: Итого с ВЗиС: | BZ33: 1
A34: Непредвиденные расходы, 2%: | BZ34: 1
A35: ИТОГО с непредвиденными: | C35: =SUM(C12:C31)-C26 -> #N/A | BZ35: 1
D36: 1 | BZ36: 1
A37: Примечание: | D37: 1) Объем работ в рублях указан с учетом НДС (20%) в соответствии с объектным сметным расчетом | BZ37: 1
D38: 2) *С момента заключения договора | BZ38: 1
D39: 1 | E39: период производства работ | BZ39: 1
D40: 1 | E40: оформление документов и актов | BZ40: 1
...
